<robot name="two_wheel_robot">

  <!-- ================= -->
  <!-- BASE LINK -->
  <!-- ================= -->

  <link name="base_link">

    <inertial>
      <mass value="2.0"/>
      <origin xyz="0 0 0"/>
      <inertia
        ixx="0.02" ixy="0" ixz="0"
        iyy="0.02" iyz="0"
        izz="0.02"/>
    </inertial>

    <visual>
      <geometry>
        <box size="0.3 0.2 0.1"/>
      </geometry>
    </visual>

    <collision>
      <geometry>
        <box size="0.3 0.2 0.1"/>
      </geometry>
    </collision>

  </link>


  <!-- ================= -->
  <!-- LEFT WHEEL -->
  <!-- ================= -->

  <link name="left_wheel">

    <inertial>
      <mass value="0.3"/>
      <origin xyz="0 0 0"/>
      <inertia
        ixx="0.001" ixy="0" ixz="0"
        iyy="0.001" iyz="0"
        izz="0.001"/>
    </inertial>

    <visual>
      <origin rpy="1.5708 0 0"/>
      <geometry>
        <cylinder radius="0.05" length="0.02"/>
      </geometry>
    </visual>

    <collision>
      <origin rpy="1.5708 0 0"/>
      <geometry>
        <cylinder radius="0.05" length="0.02"/>
      </geometry>
    </collision>

  </link>


  <!-- ================= -->
  <!-- RIGHT WHEEL -->
  <!-- ================= -->

  <link name="right_wheel">

    <inertial>
      <mass value="0.3"/>
      <origin xyz="0 0 0"/>
      <inertia
        ixx="0.001" ixy="0" ixz="0"
        iyy="0.001" iyz="0"
        izz="0.001"/>
    </inertial>

    <visual>
      <origin rpy="1.5708 0 0"/>
      <geometry>
        <cylinder radius="0.05" length="0.02"/>
      </geometry>
    </visual>

    <collision>
      <origin rpy="1.5708 0 0"/>
      <geometry>
        <cylinder radius="0.05" length="0.02"/>
      </geometry>
    </collision>

  </link>


  <!-- ================= -->
  <!-- CASTER -->
  <!-- ================= -->

  <link name="caster_wheel">

    <inertial>
      <mass value="0.1"/>
      <origin xyz="0 0 0"/>
      <inertia
        ixx="0.0001" ixy="0" ixz="0"
        iyy="0.0001" iyz="0"
        izz="0.0001"/>
    </inertial>

    <visual>
      <geometry>
        <sphere radius="0.03"/>
      </geometry>
    </visual>

    <collision>
      <geometry>
        <sphere radius="0.03"/>
      </geometry>
    </collision>

  </link>


  <!-- ================= -->
  <!-- JOINTS -->
  <!-- ================= -->

  <joint name="left_wheel_joint" type="continuous">

    <parent link="base_link"/>
    <child link="left_wheel"/>

    <origin xyz="0 0.11 -0.05"/>
    <axis xyz="0 1 0"/>

  </joint>


  <joint name="right_wheel_joint" type="continuous">

    <parent link="base_link"/>
    <child link="right_wheel"/>

    <origin xyz="0 -0.11 -0.05"/>
    <axis xyz="0 1 0"/>

  </joint>


  <joint name="caster_joint" type="fixed">

    <parent link="base_link"/>
    <child link="caster_wheel"/>

    <origin xyz="-0.12 0 -0.05"/>

  </joint>


  <!-- ================= -->
  <!-- GAZEBO FRICTION -->
  <!-- ================= -->

  <gazebo reference="left_wheel">
    <mu1>1.0</mu1>
    <mu2>1.0</mu2>
  </gazebo>

  <gazebo reference="right_wheel">
    <mu1>1.0</mu1>
    <mu2>1.0</mu2>
  </gazebo>


  <!-- ================= -->
  <!-- DIFF DRIVE PLUGIN -->
  <!-- ================= -->

  <gazebo>

    <plugin
      filename="libgazebo_ros_diff_drive.so"
      name="diff_drive_controller">

      <left_joint>left_wheel_joint</left_joint>
      <right_joint>right_wheel_joint</right_joint>

      <wheel_separation>0.22</wheel_separation>
      <wheel_radius>0.05</wheel_radius>

      <topicName>/cmd_vel</topicName>

      <odometryTopic>/odom</odometryTopic>
      <odometryFrame>odom</odometryFrame>
      <robotBaseFrame>base_link</robotBaseFrame>

    </plugin>

  </gazebo>


</robot>